Workbook

Sheet suspect number
A1: SPN | B1: EN | C1: Popis ČJ | D1: FR | E1: DE | F1: PL
A2: 81 | B2: Senzor contrapresiune catalizator | C2: Tlak výfukových plynů před DPF | D2: Druck Abgase vor DPF | E2: Pression des gaz d`échappement avant FAP | F2: Ciśnienie spalin przed DPF
A3: 84 | B3: Senzor de viteza | C3: rychlost traktoru od kol | D3: Von den Rädern ausgehende Geschwindigkeit des Traktors | E3: vitesse du tracteur à partir des roues | F3: prędkość ciągnika od kół
A4: 106 | B4: MAP | C4: Tlak vzduchu vstupujícího do motoru | D4: Luftdruck am Motoreintritt | E4: Pression de l`air entrant dans le moteur | F4: Ciśnienie powietrza wchodzącego do silnika
A5: 132 | B5: MAF | C5: Množství nasávaného vzduchu | D5: Menge Saugluft | E5: Volume de l`air aspiré | F5: Ilość zasysanego powietrza
A6: 168 | B6: Tensiune mica de alimentare | C6: Napětí baterie/hlavního napájení | D6: Spannung Batterie/Hauptversorgung | E6: Tension de l`accumulateur / alimentation principale | F6: Napięcie akumulatora/zasilania głównego
A7: 172 | B7: MAP | C7: Tlak vzduchu vstupujícího do turba | D7: Luftdruck am Turbo-Eintritt | E7: Pression de l`air entrant dans le turbo | F7: Ciśnienie powietrza wchodzącego do turbosprężarki
A8: 190 | B8: Senzor palier | C8: Otáčky motoru | D8: Motordrehzahl | E8: Tours du moteur | F8: Obroty silnika
A9: 639 | B9: Comunicare CAN #1 | C9: J1939 CAN #1 | D9: J1939 CAN #1 | E9: J1939 CAN #1 | F9: J1939 CAN #1
A10: 959 | B10: Baterie interna DEC sau timp sistem incorec | C10: Sekundy | D10: Sekunden | E10: Secondes | F10: Sekundy
A11: 1483 | B11: ECU vrea sa limiteze viteza si nu poate | C11: zdrojová adresa řízení motoru | D11: Quelladresse der Motorsteuerung | E11: adresse source de la commande du moteur | F11: adres źródłowy układu kierowniczego silnika
A12: 1761 | B12: Nivel AdBlue | C12: Hladina močoviny v nádrži | D12: Harnstoffpegel im Behälter | E12: Niveau de l`urée dans le réservoir | F12: Poziom mocznika w zbiorniku
A13: 1873 | B13: Senzor pozitie tiranti HER | C13: pozice zadního 3b- závěsu | D13: Position der hinteren Dreipunktaufhängung | E13: position de l`attelage à trois points arrière | F13: pozycja tylnego TUZ
... A90: 3516 | B90: Senzor concentratie AdBlue | C90: Koncentrace močoviny | D90: Harnstoffkonzentration | E90: Concentration de l`urée | F90: Stężenie mocznika
A91: 523126 | B91: Rear button Down | C91: Zadní bl. Tlačítko spouštění | D91: Hintere Drucktaste Senkung | E91: Bouton arrière En bas | F91: Tylny przycisk opuszczania
A93: 3511 | B93: SCR sensors voltage (5 V) ??? | C93: Napětí čidel SCR (5 V) | D93: SCR Sensorversorgungsspannung (5 V) | E93: Tension d'alimentation capteur SCR (5 V) | F93: Napięcia zasilającie czujnikow SCR
A94: 3699 | B94: Exhaust temperature low for too long | C94: Teplota výfuku je nízká příliš dlouho | D94: Abgastemperatur ist niedrig zu lang | E94: Température d'échappement est faible trop longtemps | F94: Temperatura wydecha jest niska zbyt długo
A95: 50000 | B95: OBD WARNING (Counters activated) | C95: Diagnostické varování (čítače aktivovány) | D95: Diagnosewarnung (die Zählern wird aktiviert) | E95: Avertissement de diagnostic (le compteur est activé) | F95: Ostrzeżenie diagnostyczne (licznik jest aktywny)
A96: 50001 | B96: OBD LOW LEVEL INDUCEMENT | C96: Nízké omezení výkonu (low inducement) | D96: Leistungsreduktion Schritt 1 (Low inducement) | E96: La limitation de la puissance au niveau 1 est active (Low inducement) | F96: Ograniczenie mocy na poziomie 1 aktywne (Low inducement)
A97: 50002 | B97: OBD SEVERE INDUCEMENT | C97: Vysoké omezení výkonu (severe inducement) | D97: Leistungsreduktion Schritt 2 (Severe inducement) | E97: La limitation de la puissance au niveau 2 est active (Severe inducement) | F97: Ograniczenie mocy na poziomie 2 aktywne (Severe inducement)
A98: 127 | B98: Presiune mica ulei de transmisie PS | C98: Tlak oleje v převodovce | D98: Öldruck im Getriebekasten | E98: Pression d`huile dans la boîte de vitesse | F98: Ciśnienie oleju w skrzyni biegów
A99: 177 | B99: Temperatura ulei transmisie >120 | C99: Teplota oleje v převodovce | D99: Öltemperatur im Getriebekasten | E99: Température d`huile dans la boîte de vitesse | F99: Temperatura oleju w skrzyni biegów
A100: 589 | B100: Semnal alternator W | C100: otáčky alternátoru nebo W signál | D100: Alternator-Drehzahl oder W-Signal | E100: tours d`un alternateur ou signal W | F100: Obroty alternatora lub sygnał W
A101: 598 | B101: Switch pornire ambreiaj | C101: Spínač spojkového pedálu | D101: Schalter des Kupplungspedals | E101: Interrupteur de la pédale d`embrayage | F101: Wyłącznika pedału sprzęgła
A102: 2927 | B102: Senzor virare | C102: Aktuální úhel natočení řídících kol | D102: Aktueller Drehwinkel der Steuerräder | E102: Angle actuel de la direction des roues de commande | F102: Aktualny kąt przesunięcia kół
A103: 520192 | B103: Inversorul electric | C103: Přepínač směru jízdy | D103: Umschalter der Fahrtrichtung | E103: Commutateur du sens de la marche | F103: Przełącznik kierunku jazdy
A104: 520193 | B104: P2 valve | C104: P2 ventil | D104: P2-Ventil | E104: soupape P2 | F104: Zawór P2
... A151: 520500 | B151: Engine Fuel Actuator Position | C151: Poloha Regulátoru paliva | D151: Position Kraftstoffregler | E151: Position du Régulateur du carburant | F151: Pozycja Regulatora paliwa
A152: 46 | B152: Dehidrator filtru
A153: 92 | B153: Zatížení motoru na daných otáčkách
A154: 237 | B154: VIN
A155: 513 | B155: Zatížení motoru
A156: 604 | B156: Senzor neutral cutie CL
A157: 774 | B157: Apasare buton PS HI > 7s
A158: 775 | B158: Apasare buton PS LW > 7s
A159: 1504 | B159: Senzor scaun
A160: 1898 | B160: Maneta galbena priza pozitie libera
A161: 2816 | B161: Butoane PS blocate
A162: 520197 | B162: Iesire Power Valve priza fata
A163: 520268 | B163: Senzor pozitie PTO spate
...

Sheet SPN CURS
A1: SPN | B1: EN
A2: 81 | B2: Senzor contrapresiune catalizator
A3: 84 | B3: Senzor de viteza
A4: 106 | B4: MAP
A5: 132 | B5: MAF
A6: 168 | B6: Tensiune mica de alimentare
A7: 172 | B7: MAP
A8: 190 | B8: Senzor palier
A9: 639 | B9: Comunicare CAN #1
A10: 959 | B10: Baterie interna DEC sau timp sistem incorec
A11: 1483 | B11: ECU vrea sa limiteze viteza si nu poate
A12: 1761 | B12: Nivel AdBlue
A13: 1873 | B13: Senzor pozitie tiranti HER
... A90: 3516 | B90: Senzor concentratie AdBlue
A91: 523126 | B91: Rear button Down
A93: 3511 | B93: SCR sensors voltage (5 V) ???
A94: 3699 | B94: Exhaust temperature low for too long
A95: 50000 | B95: OBD WARNING (Counters activated)
A96: 50001 | B96: OBD LOW LEVEL INDUCEMENT
A97: 50002 | B97: OBD SEVERE INDUCEMENT
A98: 127 | B98: Presiune mica ulei de transmisie PS
A99: 177 | B99: Temperatura ulei transmisie >120
A100: 589 | B100: Semnal alternator W
A101: 598 | B101: Switch pornire ambreiaj
A102: 2927 | B102: Senzor virare
A103: 520192 | B103: Inversorul electric
A104: 520193 | B104: P2 valve
... A197: 520250 | B197: Přehřátí motoru
A198: 520253 (161?) | B198: Porucha čidla před spojkou*

Sheet fmi
A1: COD | B1: ROMANA | C1: CZ | D1: DE | E1: GHJH | F1: JDHF
A2: 0 | B2: Date valide dar peste valorile nominale - cel mai server | C2: Plataná data nad povolený normální operační rozsah- kritická úroveň | D2: Gültige Daten über zulässigen normalen Arbeitsumfang hinaus - kritisches Niveau | E2: Données valables au-dessus de la plage d`exploitation standard - niveau critique | F2: Prawidłowe dane ponad dozwolonym zakresem operacyjnym - poziom krytyczny
A3: 1 | B3: Date valide dar sub valorile nominale - cel mai server | C3: Plataná data pod povolený normální operační rozsah- kritická úroveň | D3: Gültige Daten über zulässigen normalen Arbeitsumfang hinaus - kritisches Niveau | E3: Données valables au-dessous de la plage d`exploitation standard - niveau critique | F3: Prawidłowe dane poniżej dozwolonego zakresu operacyjnego - poziom krytyczny
A4: 2 | B4: date eratice intermitente sau incorecte sunt date dar sub forma incorecta | C4: Neplatná/nesprávná/přerušená data | D4: Ungültige/falsche/unterbrochene Daten | E4: Données invalides / incorrectes / interrompues | F4: Prawidłowe/nieprawidłowe/przerwane dane
A5: 3 | B5: Voltaj peste notrmal sau scurtcircuit la plus | C5: El. Napětí nad normál, nebo zkrat do plusu | D5: El. Spannung überschreitet normale Werte, oder Kurzschluss am Plus | E5: Tension él. au-dessus du standard, ou court-circuit en plus | F5: Napięcie el. poniżej normy, lub zwarcie na plusie
A6: 4 | B6: scurt cuircuit | C6: El. Napětí pod normál, nebo zkrat do GND | D6: El. Spannung überschreitet normale Werte, oder Kurzschluss in GND | E6: Tension él. au-dessous du standard, ou court-circuit en GND | F6: Napięcie el. poniżej normy, lub zwarcie na GND
A7: 5 | B7: conector desfacut | C7: El. Proud pod normál, nebo rozpojený obvod | D7: El. Spannung unterschreitet normale Werte, oder geöffneter Stromkreis | E7: Courant él. au-dessous du standard, ou circuit interrompu | F7: Napięcie el. poniżej normy, lub rozłączony obwód
A8: 6 | B8: Voltaj prea marea sau scurtcircuit | C8: El. Proud nad normál, nebo zkratovaný obvod | D8: El. Spannung überschreitet normale Werte, oder kurzgeschlossener Stromkreis | E8: Courant él. au-dessus du standard, ou circuit court-circuité | F8: Napięcie el. poniżej normy, lub zwarty obwód
A9: 7 | B9: sistemul mecanic nu raspunde sau reglaj gresit | C9: Mechanický systém neraguje, nebo mimo nastavení | D9: Mechanisches System reagiert nicht, oder außerhalb der Einstellung | E9: Système mécanique ne réagit pas ou hors limites | F9: Układ mechaniczny nie reaguje, lub poza zakresem ustawień
A10: 8 | B10: Semnal modulat necorespunzator sinusioda gresita | C10: Abnormální kmitočet, nebo PWM, případně perioda | D10: Abnormale Frequenz, oder PWM, ggf. Periode | E10: Fréquence anormale ou PWM, éventuellement période | F10: Nieprawidłowa częstotliwość, lub PWM, lub okres
A11: 9 | B11: Viteza de actualizare necporespunzatoare | C11: Abnormální rychlost aktualizace | D11: Abnormale Geschwindigkeit Aktualisierung | E11: Vitesse anormale de la mise à jour | F11: Nieprawidłowa prędkość aktualizacji
A12: 10 | B12: Actualizare de date prea rapida | C12: Abnormální rychlost změny | D12: Abnormale Geschwindigkeit der Änderung | E12: Vitesse anormale de la modification | F12: Nieprawidłowa prędkość zmiany
A13: 11 | B13: Root Cause Not Known | C13: Neznámá kořenová příčína poruchy/chyby | D13: Unbekannte Wurzelursache von Störung/Fehler | E13: Cause racine du défaut / de l`erreur inconnue | F13: Nieznana pierwotna przyczyna usterki/błędu
... A33: 31 | B33: Conditia exista | C33: Extistence podmínky pro chybu | D33: Vorhandensein einer Bedingung für Fehler | E33: Existence de la condition pour l`erreur | F33: Istnieje warunek dla błędu

Sheet identificator
A1: cod SPN | B1: fmi | C1: oc | D1: Suspect SPN | E1: Descriere FMI
A2: 29 | B2: 3 | D2: =INDEX('SPN CURS'!B:B, MATCH(identificator!A2, 'SPN CURS'!A:A, 0)) -> Accelerator lever position | E2: =INDEX(fmi!B:B, MATCH(identificator!B2, fmi!A:A, 0)) -> Voltaj peste notrmal sau scurtcircuit la plus
A3: 91 | B3: 3 | D3: =INDEX('SPN CURS'!B:B, MATCH(identificator!A3, 'SPN CURS'!A:A, 0)) -> Accelerator pedal position | E3: =INDEX(fmi!B:B, MATCH(identificator!B3, fmi!A:A, 0)) -> Voltaj peste notrmal sau scurtcircuit la plus
D4: =INDEX('SPN CURS'!B:B, MATCH(identificator!A4, 'SPN CURS'!A:A, 0)) -> #N/A | E4: =INDEX(fmi!B:B, MATCH(identificator!B4, fmi!A:A, 0)) -> Date valide dar peste valorile nominale - cel mai server
D5: =INDEX('SPN CURS'!B:B, MATCH(identificator!A5, 'SPN CURS'!A:A, 0)) -> #N/A | E5: =INDEX(fmi!B:B, MATCH(identificator!B5, fmi!A:A, 0)) -> Date valide dar peste valorile nominale - cel mai server | F5: Firul din bord care citeste senmanul din altenator
A6: 127 | D6: =INDEX('SPN CURS'!B:B, MATCH(identificator!A6, 'SPN CURS'!A:A, 0)) -> Presiune mica ulei de transmisie PS | E6: =INDEX(fmi!B:B, MATCH(identificator!B6, fmi!A:A, 0)) -> Date valide dar peste valorile nominale - cel mai server
D7: =INDEX('SPN CURS'!B:B, MATCH(identificator!A7, 'SPN CURS'!A:A, 0)) -> #N/A | E7: =INDEX(fmi!B:B, MATCH(identificator!B7, fmi!A:A, 0)) -> Date valide dar peste valorile nominale - cel mai server | F7: Vazut cu DETronicul valoarea la Nox 2 dupa ce se incalzeste daca depaseste 1000 ppm e futut senzoru
A8: 520196 | D8: =INDEX('SPN CURS'!B:B, MATCH(identificator!A8, 'SPN CURS'!A:A, 0)) -> Decuplare ambreiaj mers inainte PSF | E8: =INDEX(fmi!B:B, MATCH(identificator!B8, fmi!A:A, 0)) -> Date valide dar peste valorile nominale - cel mai server
D9: =INDEX('SPN CURS'!B:B, MATCH(identificator!A9, 'SPN CURS'!A:A, 0)) -> #N/A | E9: =INDEX(fmi!B:B, MATCH(identificator!B9, fmi!A:A, 0)) -> Date valide dar peste valorile nominale - cel mai server
D10: =INDEX('SPN CURS'!B:B, MATCH(identificator!A10, 'SPN CURS'!A:A, 0)) -> #N/A | E10: =INDEX(fmi!B:B, MATCH(identificator!B10, fmi!A:A, 0)) -> Date valide dar peste valorile nominale - cel mai server | F10: astea cu galben daca nu sunt active nu leas baga in seama, daca sunt active e problema la o mufa sau masa pe partea de SCR
A11: 3700 | D11: =INDEX('SPN CURS'!B:B, MATCH(identificator!A11, 'SPN CURS'!A:A, 0)) -> Regenerare activa blocata | E11: =INDEX(fmi!B:B, MATCH(identificator!B11, fmi!A:A, 0)) -> Date valide dar peste valorile nominale - cel mai server
D12: =INDEX('SPN CURS'!B:B, MATCH(identificator!A12, 'SPN CURS'!A:A, 0)) -> #N/A | E12: =INDEX(fmi!B:B, MATCH(identificator!B12, fmi!A:A, 0)) -> Date valide dar peste valorile nominale - cel mai server
A13: 520196 | B13: 7 | D13: =INDEX('SPN CURS'!B:B, MATCH(identificator!A13, 'SPN CURS'!A:A, 0)) -> Decuplare ambreiaj mers inainte PSF | E13: =INDEX(fmi!B:B, MATCH(identificator!B13, fmi!A:A, 0)) -> sistemul mecanic nu raspunde sau reglaj gresit
A14: 520234 | B14: 5 | D14: =INDEX('SPN CURS'!B:B, MATCH(identificator!A14, 'SPN CURS'!A:A, 0)) -> Cuplaj 4x4 VPH | E14: =INDEX(fmi!B:B, MATCH(identificator!B14, fmi!A:A, 0)) -> conector desfacut
D15: =INDEX('SPN CURS'!B:B, MATCH(identificator!A15, 'SPN CURS'!A:A, 0)) -> #N/A | E15: =INDEX(fmi!B:B, MATCH(identificator!B15, fmi!A:A, 0)) -> Date valide dar peste valorile nominale - cel mai server
D16: =INDEX('SPN CURS'!B:B, MATCH(identificator!A16, 'SPN CURS'!A:A, 0)) -> #N/A | E16: =INDEX(fmi!B:B, MATCH(identificator!B16, fmi!A:A, 0)) -> Date valide dar peste valorile nominale - cel mai server
A17: 520254 | D17: =INDEX('SPN CURS'!B:B, MATCH(identificator!A17, 'SPN CURS'!A:A, 0)) -> Avarie senzir turatie dupa ambreiaj Shaft speed behind clutch | E17: =INDEX(fmi!B:B, MATCH(identificator!B17, fmi!A:A, 0)) -> Date valide dar peste valorile nominale - cel mai server
D18: =INDEX('SPN CURS'!B:B, MATCH(identificator!A18, 'SPN CURS'!A:A, 0)) -> #N/A | E18: =INDEX(fmi!B:B, MATCH(identificator!B18, fmi!A:A, 0)) -> Date valide dar peste valorile nominale - cel mai server
D19: =INDEX('SPN CURS'!B:B, MATCH(identificator!A19, 'SPN CURS'!A:A, 0)) -> #N/A | E19: =INDEX(fmi!B:B, MATCH(identificator!B19, fmi!A:A, 0)) -> Date valide dar peste valorile nominale - cel mai server
D20: =INDEX('SPN CURS'!B:B, MATCH(identificator!A20, 'SPN CURS'!A:A, 0)) -> #N/A | E20: =INDEX(fmi!B:B, MATCH(identificator!B20, fmi!A:A, 0)) -> Date valide dar peste valorile nominale - cel mai server
D21: =INDEX('SPN CURS'!B:B, MATCH(identificator!A21, 'SPN CURS'!A:A, 0)) -> #N/A | E21: =INDEX(fmi!B:B, MATCH(identificator!B21, fmi!A:A, 0)) -> Date valide dar peste valorile nominale - cel mai server
D22: =INDEX('SPN CURS'!B:B, MATCH(identificator!A22, 'SPN CURS'!A:A, 0)) -> #N/A | E22: =INDEX(fmi!B:B, MATCH(identificator!B22, fmi!A:A, 0)) -> Date valide dar peste valorile nominale - cel mai server
D23: =INDEX('SPN CURS'!B:B, MATCH(identificator!A23, 'SPN CURS'!A:A, 0)) -> #N/A | E23: =INDEX(fmi!B:B, MATCH(identificator!B23, fmi!A:A, 0)) -> Date valide dar peste valorile nominale - cel mai server
D24: =INDEX('SPN CURS'!B:B, MATCH(identificator!A24, 'SPN CURS'!A:A, 0)) -> #N/A | E24: =INDEX(fmi!B:B, MATCH(identificator!B24, fmi!A:A, 0)) -> Date valide dar peste valorile nominale - cel mai server
D25: =INDEX('SPN CURS'!B:B, MATCH(identificator!A25, 'SPN CURS'!A:A, 0)) -> #N/A | E25: =INDEX(fmi!B:B, MATCH(identificator!B25, fmi!A:A, 0)) -> Date valide dar peste valorile nominale - cel mai server
D26: =INDEX('SPN CURS'!B:B, MATCH(identificator!A26, 'SPN CURS'!A:A, 0)) -> #N/A | E26: =INDEX(fmi!B:B, MATCH(identificator!B26, fmi!A:A, 0)) -> Date valide dar peste valorile nominale - cel mai server
D27: =INDEX('SPN CURS'!B:B, MATCH(identificator!A27, 'SPN CURS'!A:A, 0)) -> #N/A | E27: =INDEX(fmi!B:B, MATCH(identificator!B27, fmi!A:A, 0)) -> Date valide dar peste valorile nominale - cel mai server

Sheet Sheet1
A2: cod SPN | B2: fmi | C2: oc | D2: Suspect SPN | E2: Descriere FMI
A3: 50001 | B3: 14 | D3: OBD LOW LEVEL INDUCEMENT | E3: Special Instructions
A7: 3516 | B7: 10 | D7: Senzor concentratie AdBlue | E7: Actualizare de date prea rapida
A11: 3516 | B11: 5 | D11: Senzor concentratie AdBlue | E11: conector desfacut
A15: 3232 | B15: 2 | D15: Preincalzitor NOX2 | E15: date eratice intermitente sau incorecte sunt date dar sub forma incorecta
A19: 29 | D19: Accelerator lever position | E19: Date valide dar peste valorile nominale - cel mai server
A23: 32 | D23: #N/A | E23: Date valide dar peste valorile nominale - cel mai server
A27: 190 | D27: Senzor palier | E27: Date valide dar peste valorile nominale - cel mai server
B31: 31 | D31: #N/A | E31: Conditia exista

Sheet gherla
A1: cod SPN | B1: fmi | C1: oc | D1: Suspect SPN | E1: Descriere FMI
A2: 168 | B2: 0 | C2: 1 | D2: =INDEX('SPN CURS'!B:B, MATCH(identificator!A2, 'SPN CURS'!A:A, 0)) -> Accelerator lever position | E2: =INDEX(fmi!B:B, MATCH(identificator!B2, fmi!A:A, 0)) -> Voltaj peste notrmal sau scurtcircuit la plus
A3: 190 | B3: 2 | C3: 8 | D3: =INDEX('SPN CURS'!B:B, MATCH(identificator!A3, 'SPN CURS'!A:A, 0)) -> Accelerator pedal position | E3: =INDEX(fmi!B:B, MATCH(identificator!B3, fmi!A:A, 0)) -> Voltaj peste notrmal sau scurtcircuit la plus
A4: 1761 | B4: 3 | C4: 46 | D4: =INDEX('SPN CURS'!B:B, MATCH(identificator!A4, 'SPN CURS'!A:A, 0)) -> #N/A | E4: =INDEX(fmi!B:B, MATCH(identificator!B4, fmi!A:A, 0)) -> Date valide dar peste valorile nominale - cel mai server
A5: 4783 | B5: 1 | C5: 7 | D5: =INDEX('SPN CURS'!B:B, MATCH(identificator!A5, 'SPN CURS'!A:A, 0)) -> #N/A | E5: =INDEX(fmi!B:B, MATCH(identificator!B5, fmi!A:A, 0)) -> Date valide dar peste valorile nominale - cel mai server
A6: 4783 | B6: 0 | C6: 20 | D6: =INDEX('SPN CURS'!B:B, MATCH(identificator!A6, 'SPN CURS'!A:A, 0)) -> Presiune mica ulei de transmisie PS | E6: =INDEX(fmi!B:B, MATCH(identificator!B6, fmi!A:A, 0)) -> Date valide dar peste valorile nominale - cel mai server
A7: 3700 | B7: 0 | C7: 1 | D7: =INDEX('SPN CURS'!B:B, MATCH(identificator!A7, 'SPN CURS'!A:A, 0)) -> #N/A | E7: =INDEX(fmi!B:B, MATCH(identificator!B7, fmi!A:A, 0)) -> Date valide dar peste valorile nominale - cel mai server
A8: 4781 | B8: 0 | C8: 12 | D8: =INDEX('SPN CURS'!B:B, MATCH(identificator!A8, 'SPN CURS'!A:A, 0)) -> Decuplare ambreiaj mers inainte PSF | E8: =INDEX(fmi!B:B, MATCH(identificator!B8, fmi!A:A, 0)) -> Date valide dar peste valorile nominale - cel mai server
A9: 1761 | B9: 1 | C9: 71 | D9: =INDEX('SPN CURS'!B:B, MATCH(identificator!A9, 'SPN CURS'!A:A, 0)) -> #N/A | E9: =INDEX(fmi!B:B, MATCH(identificator!B9, fmi!A:A, 0)) -> Date valide dar peste valorile nominale - cel mai server
A10: 3226 | B10: 0 | C10: 1 | D10: =INDEX('SPN CURS'!B:B, MATCH(identificator!A10, 'SPN CURS'!A:A, 0)) -> #N/A | E10: =INDEX(fmi!B:B, MATCH(identificator!B10, fmi!A:A, 0)) -> Date valide dar peste valorile nominale - cel mai server
A11: 3249 | B11: 0 | C11: 1 | D11: =INDEX('SPN CURS'!B:B, MATCH(identificator!A11, 'SPN CURS'!A:A, 0)) -> Regenerare activa blocata | E11: =INDEX(fmi!B:B, MATCH(identificator!B11, fmi!A:A, 0)) -> Date valide dar peste valorile nominale - cel mai server
A12: 3245 | B12: 0 | C12: 2 | D12: =INDEX('SPN CURS'!B:B, MATCH(identificator!A12, 'SPN CURS'!A:A, 0)) -> #N/A | E12: =INDEX(fmi!B:B, MATCH(identificator!B12, fmi!A:A, 0)) -> Date valide dar peste valorile nominale - cel mai server
A13: 4363 | B13: 0 | C13: 2 | D13: =INDEX('SPN CURS'!B:B, MATCH(identificator!A13, 'SPN CURS'!A:A, 0)) -> Decuplare ambreiaj mers inainte PSF | E13: =INDEX(fmi!B:B, MATCH(identificator!B13, fmi!A:A, 0)) -> sistemul mecanic nu raspunde sau reglaj gresit
A14: 50000 | B14: 14 | C14: 127 | D14: =INDEX('SPN CURS'!B:B, MATCH(identificator!A14, 'SPN CURS'!A:A, 0)) -> Cuplaj 4x4 VPH | E14: =INDEX(fmi!B:B, MATCH(identificator!B14, fmi!A:A, 0)) -> conector desfacut
A15: 50001 | D15: =INDEX('SPN CURS'!B:B, MATCH(identificator!A15, 'SPN CURS'!A:A, 0)) -> #N/A | E15: =INDEX(fmi!B:B, MATCH(identificator!B15, fmi!A:A, 0)) -> Date valide dar peste valorile nominale - cel mai server
A16: 50002 | D16: =INDEX('SPN CURS'!B:B, MATCH(identificator!A16, 'SPN CURS'!A:A, 0)) -> #N/A | E16: =INDEX(fmi!B:B, MATCH(identificator!B16, fmi!A:A, 0)) -> Date valide dar peste valorile nominale - cel mai server
A17: 3516 | B17: 5 | C17: 127 | D17: =INDEX('SPN CURS'!B:B, MATCH(identificator!A17, 'SPN CURS'!A:A, 0)) -> Avarie senzir turatie dupa ambreiaj Shaft speed behind clutch | E17: =INDEX(fmi!B:B, MATCH(identificator!B17, fmi!A:A, 0)) -> Date valide dar peste valorile nominale - cel mai server
A18: 50013 | B18: 5 | C18: 127 | D18: =INDEX('SPN CURS'!B:B, MATCH(identificator!A18, 'SPN CURS'!A:A, 0)) -> #N/A | E18: =INDEX(fmi!B:B, MATCH(identificator!B18, fmi!A:A, 0)) -> Date valide dar peste valorile nominale - cel mai server
A19: 3216 | B19: 5 | C19: 127 | D19: =INDEX('SPN CURS'!B:B, MATCH(identificator!A19, 'SPN CURS'!A:A, 0)) -> #N/A | E19: =INDEX(fmi!B:B, MATCH(identificator!B19, fmi!A:A, 0)) -> Date valide dar peste valorile nominale - cel mai server
A20: 3226 | B20: 5 | C20: 127 | D20: =INDEX('SPN CURS'!B:B, MATCH(identificator!A20, 'SPN CURS'!A:A, 0)) -> #N/A | E20: =INDEX(fmi!B:B, MATCH(identificator!B20, fmi!A:A, 0)) -> Date valide dar peste valorile nominale - cel mai server
A21: 158 | B21: 16 | C21: 2 | D21: =INDEX('SPN CURS'!B:B, MATCH(identificator!A21, 'SPN CURS'!A:A, 0)) -> #N/A | E21: =INDEX(fmi!B:B, MATCH(identificator!B21, fmi!A:A, 0)) -> Date valide dar peste valorile nominale - cel mai server
A22: 132 | B22: 1 | C22: 127 | D22: =INDEX('SPN CURS'!B:B, MATCH(identificator!A22, 'SPN CURS'!A:A, 0)) -> #N/A | E22: =INDEX(fmi!B:B, MATCH(identificator!B22, fmi!A:A, 0)) -> Date valide dar peste valorile nominale - cel mai server
A23: 4334 | B23: 4 | C23: 127 | D23: =INDEX('SPN CURS'!B:B, MATCH(identificator!A23, 'SPN CURS'!A:A, 0)) -> #N/A | E23: =INDEX(fmi!B:B, MATCH(identificator!B23, fmi!A:A, 0)) -> Date valide dar peste valorile nominale - cel mai server
A24: 1761 | B24: 4 | C24: 127 | D24: =INDEX('SPN CURS'!B:B, MATCH(identificator!A24, 'SPN CURS'!A:A, 0)) -> #N/A | E24: =INDEX(fmi!B:B, MATCH(identificator!B24, fmi!A:A, 0)) -> Date valide dar peste valorile nominale - cel mai server
A25: 3031 | B25: 4 | C25: 127 | D25: =INDEX('SPN CURS'!B:B, MATCH(identificator!A25, 'SPN CURS'!A:A, 0)) -> #N/A | E25: =INDEX(fmi!B:B, MATCH(identificator!B25, fmi!A:A, 0)) -> Date valide dar peste valorile nominale - cel mai server
A26: 3361 | B26: 5 | C26: 127 | D26: =INDEX('SPN CURS'!B:B, MATCH(identificator!A26, 'SPN CURS'!A:A, 0)) -> #N/A | E26: =INDEX(fmi!B:B, MATCH(identificator!B26, fmi!A:A, 0)) -> Date valide dar peste valorile nominale - cel mai server
A27: 5394 | B27: 5 | C27: 18 | D27: =INDEX('SPN CURS'!B:B, MATCH(identificator!A27, 'SPN CURS'!A:A, 0)) -> #N/A | E27: =INDEX(fmi!B:B, MATCH(identificator!B27, fmi!A:A, 0)) -> Date valide dar peste valorile nominale - cel mai server
